Workbook

Sheet Plan1
A1: Matrícula | B1: Chefia Imediata - Nome | C1: Função | D1: Centro Resultado | E1: Email
A2: 17102754 | B2: ADRIANE DUARTE BOFF SANTOS | C2: =VLOOKUP(A2,Plan2!A:D,3,FALSE) -> CHEFE DE ENFERMAGEM SERVIÇOS SAUDE | D2: =VLOOKUP(A2,Plan2!A:D,4,FALSE) -> HU - CENTRO OBSTETRICO | E2: =VLOOKUP(A2,Plan3!A:C,3,FALSE) -> adriane.boff@gampcanoas.com.br
A3: 17104940 | B3: AGATA RAFAELA PADILHA PAIM | C3: =VLOOKUP(A3,Plan2!A:D,3,FALSE) -> ENFERMEIRO UNIDADE DE INTERNAÇÃO (H | D3: =VLOOKUP(A3,Plan2!A:D,4,FALSE) -> HU - UNID INTERN 8º A | E3: =VLOOKUP(A3,Plan3!A:C,3,FALSE) -> agatarppaim@gmail.com
A4: 17101267 | B4: AGNES TURELLA FAGUNDES | C4: =VLOOKUP(A4,Plan2!A:D,3,FALSE) -> ENFERMEIRO SR IMAGEM | D4: =VLOOKUP(A4,Plan2!A:D,4,FALSE) -> HU - SR IMAGEM | E4: =VLOOKUP(A4,Plan3!A:C,3,FALSE) -> agnes.fagundes@gampcanoas.com.br
A5: 17104724 | B5: ALESSANDRA LANG DE QUADROS | C5: =VLOOKUP(A5,Plan2!A:D,3,FALSE) -> ENFERMEIRO FOLG/FERISTA CO E PA OBS | D5: =VLOOKUP(A5,Plan2!A:D,4,FALSE) -> HU - UI PRONTO ATEND OBSTETRICO | E5: =VLOOKUP(A5,Plan3!A:C,3,FALSE) -> alessandra.quadros@gampcanoas.com.br
A6: 17103303 | B6: ALEXANDRE DE OLIVEIRA DILELIO | C6: =VLOOKUP(A6,Plan2!A:D,3,FALSE) -> ENFERMEIRO CAPS (HU) | D6: =VLOOKUP(A6,Plan2!A:D,4,FALSE) -> HU - CAPS AMANHECER | E6: =VLOOKUP(A6,Plan3!A:C,3,FALSE) -> adellucca7@gmail.com
A7: 17100730 | B7: ALINE KLAUS | C7: =VLOOKUP(A7,Plan2!A:D,3,FALSE) -> ENFERMEIRO ENDOSCOPIA (HU) | D7: =VLOOKUP(A7,Plan2!A:D,4,FALSE) -> HU - ENDOSCOPIA | E7: =VLOOKUP(A7,Plan3!A:C,3,FALSE) -> aline.klaus@gampcanoas.com.br
A8: 17101235 | B8: ANA BEATRIZ CARVALHO DA SILVA | C8: =VLOOKUP(A8,Plan2!A:D,3,FALSE) -> SUPERVISOR RECEPÇÃO (HU) | D8: =VLOOKUP(A8,Plan2!A:D,4,FALSE) -> HU - RECEPÇÃO | E8: =VLOOKUP(A8,Plan3!A:C,3,FALSE) -> ana.carvalho@gampcanoas.com.br
A9: 17102323 | B9: ANA CAROLINA DELLANI COELO PAPALÉO | C9: =VLOOKUP(A9,Plan2!A:D,3,FALSE) -> COORDENADOR DE SERVIÇOS (HU) | D9: =VLOOKUP(A9,Plan2!A:D,4,FALSE) -> HU - CAPS NOVOS TEMPOS | E9: =VLOOKUP(A9,Plan3!A:C,3,FALSE) -> ana.papaleo@gampcanoas.com.br
A10: 16100559 | B10: ANA CASSIA DA FONSECA | C10: =VLOOKUP(A10,Plan2!A:D,3,FALSE) -> TÉCNICO EM RADIOLOGIA LÍDER (HU) | D10: =VLOOKUP(A10,Plan2!A:D,4,FALSE) -> HU - Radiologia | E10: =VLOOKUP(A10,Plan3!A:C,3,FALSE) -> tnr.anafonseca@gmail.com
A11: 17108324 | B11: ANA PAULA CAZARA | C11: =VLOOKUP(A11,Plan2!A:D,3,FALSE) -> COORDENADOR DE OPME | D11: =VLOOKUP(A11,Plan2!A:D,4,FALSE) -> HU - ESTOQUE OPME | E11: =VLOOKUP(A11,Plan3!A:C,3,FALSE) -> APCAZARA@GMAIL.COM
A12: 17103184 | B12: ANDRE KUCK | C12: =VLOOKUP(A12,Plan2!A:D,3,FALSE) -> ANALISTA DE LOGISTICA JR | D12: =VLOOKUP(A12,Plan2!A:D,4,FALSE) -> HU - Almoxarifado | E12: =VLOOKUP(A12,Plan3!A:C,3,FALSE) -> andre.kuck@gampcanoas.com.br
A13: 17102390 | B13: ANDRESA DUARTE CARDOSO | C13: =VLOOKUP(A13,Plan2!A:D,3,FALSE) -> COORDENADOR DE SERVIÇOS (HU) | D13: =VLOOKUP(A13,Plan2!A:D,4,FALSE) -> HU - CAPS RECANTO DOS GIRASSOIS | E13: =VLOOKUP(A13,Plan3!A:C,3,FALSE) -> andresa.cardoso@gampcanoas.com.br
... A136: 17102761 | B136: VLADIMIR ROBERTO DA SILVA SANTOS | C136: =VLOOKUP(A136,Plan2!A:D,3,FALSE) -> ENFERMEIRO CAPS (HU) | D136: =VLOOKUP(A136,Plan2!A:D,4,FALSE) -> HU - CAPS TRAVESSIA | E136: =VLOOKUP(A136,Plan3!A:C,3,FALSE) -> vladsilva_26@yahoo.com.br

Sheet Plan2
A1: Matrícula | B1: Nome | C1: Função - Nome | D1: Centro de Resultado - Nome
A2: 16102008 | B2: FERNANDA BASTOS CORREA | C2: COORDENADOR DE ATENDIMENTO (HU) | D2: HU - Faturamento
A3: 18000221 | B3: ANTONIO HELDER LOIOLA AMORIM | C3: MEDICO CARDIOLOGISTA | D3: HU - CTI ADULTO
A4: 17102535 | B4: CRISTINE GOMES MACHADO | C4: COORDENADOR DE CONTRATOS | D4: HU - Administração
A5: 17103184 | B5: ANDRE KUCK | C5: ANALISTA DE LOGISTICA JR | D5: HU - Almoxarifado
A6: 17102443 | B6: GUILHERME PEDROZO | C6: AUXILIAR DE SUPRIMENTOS (HU) | D6: HU - Almoxarifado
A7: 16101776 | B7: EDMILSON SANTANA NASCIMENTO | C7: COMPRADOR PL | D7: HU - COMPRAS
A8: 16102199 | B8: DEIVID LETSCH RAFAELLI | C8: ASSISTENTE CONTABIL | D8: HU - Contabilidade
A9: 17103903 | B9: JULIANO KENGERISKI LEIVAS | C9: ANALISTA DE LOGISTICA JR | D9: HU - Almoxarifado
A10: 17100456 | B10: LUCIANE KAVICHESKI DA ROSA | C10: TÉCNICO DE ENFERMAGEM AMBULATÓRIO ( | D10: HU - AMBULATORIO
A11: 17100507 | B11: ANA CAROLINA KOECHE ROCHA | C11: TÉCNICO DE ENFERMAGEM AMBULATÓRIO ( | D11: HU - AMBULATORIO
A12: 17102037 | B12: ROBERTA CAROLINE FEIJO RIZZI DA SILVA | C12: CHEFIA REGULAÇÃO JUNIOR | D12: HU - N.I.R
A13: 16100584 | B13: DAIANI CRISTINI WURTENBERGER DE OLIVEIRA | C13: TÉCNICO DE ENFERMAGEM AMBULATÓRIO ( | D13: HU - AMBULATORIO
... A1550: 17107455 | B1550: LETICIA SILVA DE AVILA | C1550: AGENTE DE ATENDIMENTO I (HU) | D1550: HU - RECEPÇÃO

Sheet Plan3
A1: Matrícula | B1: Nome | C1: E-Mail
A2: 18000230 | B2: ANA PAULA BACK DE SOUZA | C2: maira.anselmo@gampcanoas.com.br
A3: 18000240 | B3: CLAUDIOMAR GARCIA | C3: claudiomrg360@hotmail.com
A4: 16100037 | B4: CARINE OLIVEIRA PINHEIRO | C4: carinelivre21@gmail.com
A5: 16100106 | B5: GIOVANA CORREA | C5: giovana.correa@yahoo.com.br
A6: 17100207 | B6: ISABEL CRISTINA DA ROCHA | C6: isabelcristinadarocha967@gmail.com
A7: 16100999 | B7: TIERRE SOARES MONTEIRO | C7: tierremonteiro2011@hotmail.com
A8: 16101010 | B8: SUSANA MORAES DA CUNHA | C8: susymoraes72@yahoo.com.br
A9: 16101039 | B9: MICHELE SANTOS DA SILVA | C9: michelonasantos@gmail.com
A10: 18000087 | B10: ANGELA BEATRIZ DOS SANTOS LEITE | C10: everton.quadros@gampcanoas.com.br
A11: 16101114 | B11: CAROLINA CHAVES TAFFAREL | C11: caroltaffarel@gmail.com
A12: 18000009 | B12: PATRICIA DA SILVA SIMIÃO | C12: angelica.santos@gampcanoas.com.br
A13: 18000035 | B13: MAIRA ROSA ANSELMO | C13: maira.anselmo@gampcanoas.com.br
... A43: 16102301 | B43: LUCAS LUZ ROCHA | C43: lrocha1970@hotmail.com
A44: 16100002 | B44: FATIMA CATARINA MAYER
A45: 16100048 | B45: PRISCILA RUAS HUBNER | C45: priscila.ruas@gampcanoas.com.br
A46: 16100694 | B46: CRISTINA ALVES VIDAL | C46: ana.alice@gampcanoas.com.br
A47: 16101138 | B47: SOLANGE GOMES MACIEL | C47: fabiana.valenca@maededeus.com.br
A48: 16101705 | B48: ANA ALICE DA SILVA | C48: ana.alice@gampcanoas.com.br
A49: 16100264 | B49: MARIA LUCIA KOBER CARLSON | C49: luciakobercarlson@hotmail.com
A50: 16100725 | B50: SOLANGE ERONITA DE CAMARGO | C50: sol.decamargo@gmail.com
A51: 16100779 | B51: JOCILENE LUISA SILVEIRA FLORES | C51: leneluisa-@hotmail.com
A52: 16100787 | B52: ANA LAIRES MOURA DE SOUZA | C52: natana.walasco@maededeus.com.br
A53: 16100964 | B53: CLEONIR FÁTIMA OLDRA | C53: ana.alice@gampcanoas.com.br
A54: 16101608 | B54: ELIANE SILVEIRA MARQUES | C54: ana.alice@gampcanoas.com.br
A55: 16101660 | B55: CLAIR ZORAIDE DOS SANTOS | C55: ana.alice@gampcanoas.com.br
A56: 16102089 | B56: DARCILA RODRIGUES FERRAZ | C56: natana.walasco@maededeus.com.br
... A70: 16101174 | B70: SAULO RODRIGO DA SILVA FRAGA | C70: saulo.fraga@gampcanoas.com.br
A71: 16101049 | B71: ANA PAULA PETRONA
A72: 17100456 | B72: LUCIANE KAVICHESKI DA ROSA | C72: elaine.gomes@gampcanoas.com.br
A73: 17100507 | B73: ANA CAROLINA KOECHE ROCHA | C73: anakoeche@bol.com.br
A74: 17102037 | B74: ROBERTA CAROLINE FEIJO RIZZI DA SILVA | C74: roberta.silva@gampcanoas.com.br
A75: 16100584 | B75: DAIANI CRISTINI WURTENBERGER DE OLIVEIRA | C75: daianiwurtenberger@gmail.com
A76: 17100120 | B76: CARINA VELASQUE RODRIGUES | C76: carinavelasquerodrigues@gmail.com
A77: 17100133 | B77: JANETE TEIXEIRA FERREIRA | C77: janetefrrr@gmail.com
A78: 17100439 | B78: EDINA MARIA ALMEIDA | C78: elaine.gomes@gampcanoas.com.br
A79: 17100644 | B79: LUCIANE RAMOS VIEIRA | C79: lu.cardioped@hotmail.com
A80: 17101819 | B80: BRUNA CAMPOS COLA | C80: bruna.cola@gampcanoas.com.br
A81: 17102940 | B81: CINTIA MATTOS MACHADO | C81: cintia_nsr09@hotmail.com
A82: 17103958 | B82: MARCELE CRISTINA ONANTSCHENKO | C82: chenko.marcele@hotmail.com
...
