Workbook

Sheet MAPA
A1: Mapa do Lactário
A4: DATA : 10/10/2019
A6: =A1 -> Mapa do Lactário | F6: 0 | G6: =A4 -> DATA : 10/10/2019
A7: LEITO | B7: NOME DO PACIENTE | C7: VIA | D7: VOLUME (ml) | E7: LM | F7: FÓRMULA | G7: FREQUÊNCIA | H7: OBSERVAÇÃO
A8: 4001 | B8: OTAVIO DA SILVEIRA LEMOS,6M | C8: SNE | D8: 120 | F8: FL HIDROLISADA (15,9%) | G8: 3/3H | H8: FRASCO AGUA 300ML - 06H
A9: 4002 | B9: BEATRIZ RUAS DA SILVA, 1A11M | C9: SNE | D9: 90 | F9: FORTINI | G9: 3/3H | H9: FRASCO AGUA 300ML - 06H
A10: 4003 | B10: ANTHONIA JULIA RANZAN 2A5M | C10: VO | D10: 240 | F10: LV + ACHOCOLATADO | G10: 7:30-15-21-24H
A11: 4004 | B11: KEIVID LUAN KLAUCK 11A | C11: SNE | D11: 60 | F11: FL HIDROLISADA | G11: 3/3H | H11: FRASCO AGUA 300ML - 06H
A12: 4005 | B12: BIANCA GABRIELLY MACHADO, 6M | C12: SNE | D12: 70 | F12: FL 1º SEMESTRE | G12: 3/3H | H12: FRASCO AGUA 300ML - 06H
A13: 4006
A14: 4007
A15: 4008 | B15: MARIA FLORÊNCIA A. M. DUARTE, 2A3M | C15: SNE | D15: 100 | E15: - | F15: FORTINI | G15: 3/3H | H15: FRASCO AGUA 300ML - 06H
A16: 4009
A17: 4010 | B17: ALICE MANUELLA DORNELES, 8M | C17: SNE | D17: 140 | F17: FL AA + MMD ROSA COMUM | G17: 3/3H | H17: FRASCO AGUA 300ML - 06H
A19: INTERNAÇÃO PEDIÁTRICA
F20: DATA: | G20: =A4 -> DATA : 10/10/2019
A21: LEITO | B21: NOME DO PACIENTE | C21: VIA | D21: VOLUME | E21: LM | F21: FÓRMULA | G21: HORÁRIOS | H21: OBSERVAÇÃO
A22: 4101 A | B22: LOUISE REOLON CHUVAS, 4A | C22: VO | D22: 240 | F22: LV+ACHOCOLATADO | G22: 7:30-15-21H
A23: 4101 B
A24: 4101 C
A25: 4102 A
A26: 4102 B | B26: LUIZ FELIPE ELIAS SILVA, 9M | C26: VO | D26: 200 | F26: FL 2º SEMESTRE | G26: 3/3H (-18 -03H -09H)
A27: 4102 C
A28: 4103 A
A29: 4103 B
A30: 4103 C
A31: 4104 A
A32: 4104 B
A33: 4104 C
A34: 4105 A
A35: 4105 B
A36: 4105 C
A37: 4106 A | B37: ISABELA COUTO 2A | C37: VO | D37: 240 | F37: LV+ACHO | G37: 7:30-15-21-24
A38: 4106 B
A39: 4106 C
A40: 4107 A
A41: 4107 B
A42: 4107 C
A43: 4108 A
A44: 4108 B
...

Sheet Protocolo de Entrega
A1: PROTOCOLO DE ENTREGA
A3: =MAPA!A4 -> DATA : 10/10/2019
A4: UTI PEDIÁTRICA
A5: =A1 -> PROTOCOLO DE ENTREGA | C5: DATA: | D5: =MAPA!A4 -> DATA : 10/10/2019 | F5: Horário:
A6: LEITO | B6: NOME DO PACIENTE | C6: VOLUME (ml) | D6: VIA | E6: LM | F6: FÓRMULA | G6: RECEBIMENTO
A7: 4001 | B7: =MAPA!B8 -> OTAVIO DA SILVEIRA LEMOS,6M | C7: =MAPA!D8 -> 120 | D7: =MAPA!C8 -> SNE | E7: =MAPA!E8 -> 0 | F7: =MAPA!F8 -> FL HIDROLISADA (15,9%)
A8: 4002 | B8: =MAPA!B9 -> BEATRIZ RUAS DA SILVA, 1A11M | C8: =MAPA!D9 -> 90 | D8: =MAPA!C9 -> SNE | E8: =MAPA!E9 -> 0 | F8: =MAPA!F9 -> FORTINI
A9: 4003 | B9: =MAPA!B10 -> ANTHONIA JULIA RANZAN 2A5M | C9: =MAPA!D10 -> 240 | D9: =MAPA!C10 -> VO | E9: =MAPA!E10 -> 0 | F9: =MAPA!F10 -> LV + ACHOCOLATADO
A10: 4004 | B10: =MAPA!B11 -> KEIVID LUAN KLAUCK 11A | C10: =MAPA!D11 -> 60 | D10: =MAPA!C11 -> SNE | E10: =MAPA!E11 -> 0 | F10: =MAPA!F11 -> FL HIDROLISADA
A11: 4005 | B11: =MAPA!B12 -> BIANCA GABRIELLY MACHADO, 6M | C11: =MAPA!D12 -> 70 | D11: =MAPA!C12 -> SNE | E11: =MAPA!E12 -> 0 | F11: =MAPA!F12 -> FL 1º SEMESTRE
A12: 4006 | B12: =MAPA!B13 -> 0 | C12: =MAPA!D13 -> 0 | D12: =MAPA!C13 -> 0 | E12: =MAPA!E13 -> 0 | F12: =MAPA!F13 -> 0
A13: 4007 | B13: =MAPA!B14 -> 0 | C13: =MAPA!D14 -> 0 | D13: =MAPA!C14 -> 0 | E13: =MAPA!E14 -> 0 | F13: FL 1º SEMESTRE (NAN CONFOR1)
A14: 4008 | B14: =MAPA!B15 -> MARIA FLORÊNCIA A. M. DUARTE, 2A3M | C14: =MAPA!D15 -> 100 | D14: =MAPA!C15 -> SNE | E14: =MAPA!E15 -> - | F14: =MAPA!F15 -> FORTINI
A15: 4009 | B15: =MAPA!B16 -> 0 | C15: =MAPA!D16 -> 0 | D15: =MAPA!C16 -> 0 | E15: =MAPA!E16 -> 0 | F15: =MAPA!F16 -> 0
A16: 4010 | B16: =MAPA!B17 -> ALICE MANUELLA DORNELES, 8M | C16: =MAPA!D17 -> 140 | D16: =MAPA!C17 -> SNE | E16: =MAPA!E17 -> 0 | F16: =MAPA!F17 -> FL AA + MMD ROSA COMUM
A18: INTERNAÇÃO PEDIÁTRICA
A19: =A5 -> PROTOCOLO DE ENTREGA | C19: DATA: | D19: =MAPA!A4 -> DATA : 10/10/2019 | F19: Horário:
A20: LEITO | B20: NOME DO PACIENTE | C20: VOLUME (ml) | D20: VIA | E20: LM | F20: FÓRMULA | G20: RECEBIMENTO
A21: 4101 A | B21: =MAPA!B22 -> LOUISE REOLON CHUVAS, 4A | C21: =MAPA!D22 -> 240 | D21: =MAPA!C22 -> VO | E21: =MAPA!E22 -> 0 | F21: =MAPA!F22 -> LV+ACHOCOLATADO
A22: 4101 B | B22: =MAPA!B23 -> 0 | C22: =MAPA!D23 -> 0 | D22: =MAPA!C23 -> 0 | E22: =MAPA!E23 -> 0 | F22: =MAPA!F23 -> 0
A23: 4101 C | B23: =MAPA!B24 -> 0 | C23: =MAPA!D24 -> 0 | D23: =MAPA!C24 -> 0 | E23: =MAPA!E24 -> 0 | F23: =MAPA!F24 -> 0
A24: 4102 A | B24: =MAPA!B25 -> 0 | C24: =MAPA!D25 -> 0 | D24: =MAPA!C25 -> 0 | E24: =MAPA!E25 -> 0 | F24: =MAPA!F25 -> 0
A25: 4102 B | B25: =MAPA!B26 -> LUIZ FELIPE ELIAS SILVA, 9M | C25: =MAPA!D26 -> 200 | D25: =MAPA!C26 -> VO | E25: =MAPA!E26 -> 0 | F25: =MAPA!F26 -> FL 2º SEMESTRE
A26: 4102 C | B26: =MAPA!B27 -> 0 | C26: =MAPA!D27 -> 0 | D26: =MAPA!C27 -> 0 | E26: =MAPA!E27 -> 0 | F26: =MAPA!F27 -> 0
A27: 4103 A | B27: =MAPA!B28 -> 0 | C27: =MAPA!D28 -> 0 | D27: =MAPA!C28 -> 0 | E27: =MAPA!E28 -> 0 | F27: =MAPA!F28 -> 0
A28: 4103 B | B28: =MAPA!B29 -> 0 | C28: =MAPA!D29 -> 0 | D28: =MAPA!C29 -> 0 | E28: =MAPA!E29 -> 0 | F28: =MAPA!F30 -> 0
A29: 4103 C | B29: =MAPA!B30 -> 0 | C29: =MAPA!D30 -> 0 | D29: =MAPA!C30 -> 0 | E29: =MAPA!E30 -> 0 | F29: =MAPA!#REF! -> #REF!
A30: 4104 A | B30: =MAPA!B31 -> 0 | C30: =MAPA!D31 -> 0 | D30: =MAPA!C31 -> 0 | E30: =MAPA!E31 -> 0 | F30: =MAPA!F31 -> 0
A31: 4104 B | B31: =MAPA!B32 -> 0 | C31: =MAPA!D32 -> 0 | D31: =MAPA!C32 -> 0 | E31: =MAPA!E32 -> 0 | F31: =MAPA!F32 -> 0
A32: 4104 C | B32: =MAPA!B33 -> 0 | C32: =MAPA!D33 -> 0 | D32: =MAPA!C33 -> 0 | E32: =MAPA!E33 -> 0 | F32: =MAPA!F33 -> 0
A33: 4105 A | B33: =MAPA!B34 -> 0 | C33: =MAPA!D34 -> 0 | D33: =MAPA!C34 -> 0 | E33: =MAPA!E34 -> 0 | F33: =MAPA!F34 -> 0
A34: 4105 B | B34: =MAPA!B35 -> 0 | C34: =MAPA!D35 -> 0 | D34: =MAPA!C35 -> 0 | E34: =MAPA!E35 -> 0 | F34: =MAPA!F35 -> 0
A35: 4105 C | B35: =MAPA!B36 -> 0 | C35: =MAPA!D36 -> 0 | D35: =MAPA!C36 -> 0 | E35: =MAPA!E36 -> 0 | F35: =MAPA!F36 -> 0
A36: 4106 A | B36: =MAPA!B37 -> ISABELA COUTO 2A | C36: =MAPA!D37 -> 240 | D36: =MAPA!C37 -> VO | E36: =MAPA!E37 -> 0 | F36: =MAPA!F37 -> LV+ACHO
A37: 4106 B | B37: =MAPA!B38 -> 0 | C37: =MAPA!D38 -> 0 | D37: =MAPA!C38 -> 0 | E37: =MAPA!E38 -> 0 | F37: =MAPA!F38 -> 0
A38: 4106 C | B38: =MAPA!B39 -> 0 | C38: =MAPA!D39 -> 0 | D38: =MAPA!C39 -> 0 | E38: =MAPA!E39 -> 0 | F38: =MAPA!F39 -> 0
A39: 4107 A | B39: =MAPA!B40 -> 0 | C39: =MAPA!D40 -> 0 | D39: =MAPA!C40 -> 0 | E39: =MAPA!E40 -> 0 | F39: =MAPA!F40 -> 0
A40: 4107 B | B40: =MAPA!B41 -> 0 | C40: =MAPA!D41 -> 0 | D40: =MAPA!C41 -> 0 | E40: =MAPA!E41 -> 0 | F40: =MAPA!F41 -> 0
A41: 4107 C | B41: =MAPA!B42 -> 0 | C41: =MAPA!D42 -> 0 | D41: =MAPA!C42 -> 0 | E41: =MAPA!E42 -> 0 | F41: =MAPA!F42 -> 0
... A53: 4111 C | B53: =MAPA!B54 -> 0 | C53: =MAPA!D54 -> 0 | D53: =MAPA!C54 -> 0 | E53: =MAPA!E54 -> - | F53: =MAPA!F54 -> 0
...

Sheet Estatística
A1: LACTÁRIO | B1: ESTATÍSTICA
B2: =MAPA!A4 -> DATA : 10/10/2019
B3: Fórmula | C3: Diluição | D3: vol. horário | E3: vol. horário + amostra | F3: fórmula (2 horários - g) | G3: Água (ml) | H3: Lote | I3: Funcionário
B4: FL PREMATURO (Aptamil Pré) | C4: 0.165 | D4: 66 | E4: =(D4*2)+200 -> 332 | F4: =E4*C4 -> 54.78 | G4: =E4*90% -> 298.8
B5: FL TRANSIÇÃO (Aptamil Pré Transition) | C5: 0.153 | D5: 43 | E5: =(D5*2)+200 -> 286 | F5: =E5*C5 -> 43.758 | G5: =E5*90% -> 257.4
B6: FL 1º SEMESTRE (Nestogeno 1) | C6: 0.135 | D6: 810 | E6: =(D6*2)+200 -> 1820 | F6: =E6*C6 -> 245.7 | G6: =E6*90% -> 1638
B7: FL 1º SEMESTRE (Aptamil 1) | C7: 0.137 | D7: 100 | E7: =(D7*2)+200 -> 400 | F7: =E7*C7 -> 54.8 | G7: =E7*90% -> 360
B8: FL 1º SEMESTRE 20% (Nestogeno 1) | C8: 0.2 | D8: 80 | E8: =(D8*2)+200 -> 360 | F8: =E8*C8 -> 72 | G8: =E8*90% -> 324
B9: FL 2º SEMESTRE (Nestogeno 2) | C9: 0.142 | D9: 440 | E9: =(D9*2)+200 -> 1080 | F9: =E9*C9 -> 153.36 | G9: =E9*90% -> 972
B10: FL 2º SEMESTRE 21% (Nestogeno 2) | C10: 0.21 | D10: 210 | E10: =(D10*2)+200 -> 620 | F10: =E10*C10 -> 130.2 | G10: =E10*90% -> 558
B11: FL 2º SEMESTRE (Nan 2) | C11: 0.141 | E11: =(D11*2)+200 -> 200 | F11: =E11*C11 -> 28.2 | G11: =E11*90% -> 180
B12: FL 2º SEMESTRE (Aptamil 2) | C12: 0.147 | D12: 200 | E12: =(D12*2)+200 -> 600 | F12: =E12*C12 -> 88.2 | G12: =E12*90% -> 540
B13: FL ANTI-REFLUXO (Nan AR) | C13: 0.133 | E13: =(D13*2)+200 -> 200 | F13: =E13*C13 -> 26.6 | G13: =E13*90% -> 180
B14: FL HIDROLISADA (Pregomin) | C14: 0.129 | D14: 125 | E14: =(D14*2)+200 -> 450 | F14: =E14*C14 -> 58.05 | G14: =E14*90% -> 405
B15: FL HIDROLISADA (Pregomin) 14,9% | C15: 0.149 | E15: =(D15*2)+200 -> 200 | F15: =E15*C15 -> 29.8 | G15: =E15*90% -> 180
B16: FL HIDROLISADA (Pregomin) 19,5% | C16: 0.195 | D16: 120 | E16: =(D16*2)+200 -> 440 | F16: =E16*C16 -> 85.8 | G16: =E16*90% -> 396
B17: FL AA (Neocate) | C17: 0.138 | D17: 190 | E17: =(D17*2)+200 -> 580 | F17: =E17*C17 -> 80.04 | G17: =E17*90% -> 522
B18: Infatrini | C18: 0.2 | E18: =(D18*2)+200 -> 200 | F18: =E18*C18 -> 40 | G18: =E18*90% -> 180
B19: Fortini 20,3% | C19: 0.203 | D19: 100 | E19: =(D19*2)+200 -> 400 | F19: =E19*C19 -> 81.2 | G19: =E19*90% -> 360
B20: Fortini 25,1% | C20: 0.251 | E20: =(D20*2)+200 -> 200 | F20: =E20*C20 -> 50.2 | G20: =E20*90% -> 180
B21: Fortini 30% | C21: 0.3 | E21: =(D21*2)+200 -> 200 | F21: =E21*C21 -> 60 | G21: =E21*90% -> 180
A24: LEITO | B24: NOME DO PACIENTE | C24: VOLUME (ml) | D24: LM | E24: FÓRMULA
A25: 4001 | B25: =MAPA!B8 -> OTAVIO DA SILVEIRA LEMOS,6M | C25: =MAPA!D8 -> 120 | D25: =MAPA!E8 -> 0 | E25: =MAPA!F8 -> FL HIDROLISADA (15,9%)
A26: 4002 | B26: =MAPA!B9 -> BEATRIZ RUAS DA SILVA, 1A11M | C26: =MAPA!D9 -> 90 | D26: =MAPA!E9 -> 0 | E26: =MAPA!F9 -> FORTINI
A27: 4003 | B27: =MAPA!B10 -> ANTHONIA JULIA RANZAN 2A5M | C27: =MAPA!D10 -> 240 | D27: =MAPA!E10 -> 0 | E27: =MAPA!F10 -> LV + ACHOCOLATADO
A28: 4004 | B28: =MAPA!B11 -> KEIVID LUAN KLAUCK 11A | C28: =MAPA!D11 -> 60 | D28: =MAPA!E11 -> 0 | E28: =MAPA!F11 -> FL HIDROLISADA
A29: 4005 | B29: =MAPA!B12 -> BIANCA GABRIELLY MACHADO, 6M | C29: =MAPA!D12 -> 70 | D29: =MAPA!E12 -> 0 | E29: =MAPA!F12 -> FL 1º SEMESTRE
A30: 4006 | B30: =MAPA!B13 -> 0 | C30: =MAPA!D13 -> 0 | D30: =MAPA!E13 -> 0 | E30: =MAPA!F13 -> 0
A31: 4007 | B31: =MAPA!B14 -> 0 | C31: =MAPA!D14 -> 0 | D31: =MAPA!E14 -> 0 | E31: =MAPA!F14 -> 0
A32: 4008 | B32: =MAPA!B15 -> MARIA FLORÊNCIA A. M. DUARTE, 2A3M | C32: =MAPA!D15 -> 100 | D32: =MAPA!E15 -> - | E32: =MAPA!F15 -> FORTINI
A33: 4009 | B33: =MAPA!B16 -> 0 | C33: =MAPA!D16 -> 0 | D33: =MAPA!E16 -> 0 | E33: =MAPA!F16 -> 0
A34: 4010 | B34: =MAPA!B17 -> ALICE MANUELLA DORNELES, 8M | C34: =MAPA!D17 -> 140 | D34: =MAPA!E17 -> 0 | E34: =MAPA!F17 -> FL AA + MMD ROSA COMUM
A35: 4101 A | B35: =MAPA!B22 -> LOUISE REOLON CHUVAS, 4A | C35: =MAPA!D22 -> 240 | D35: =MAPA!E22 -> 0 | E35: =MAPA!F22 -> LV+ACHOCOLATADO
A36: 4101 B | B36: =MAPA!B23 -> 0 | C36: =MAPA!D23 -> 0 | D36: =MAPA!E23 -> 0 | E36: =MAPA!F23 -> 0
A37: 4101 C | B37: =MAPA!B24 -> 0 | C37: =MAPA!D24 -> 0 | D37: =MAPA!E24 -> 0 | E37: =MAPA!F24 -> 0
A38: 4102 A | B38: =MAPA!B25 -> 0 | C38: =MAPA!D25 -> 0 | D38: =MAPA!E25 -> 0 | E38: =MAPA!F25 -> 0
A39: 4102 B | B39: =MAPA!B26 -> LUIZ FELIPE ELIAS SILVA, 9M | C39: =MAPA!D26 -> 200 | D39: =MAPA!E26 -> 0 | E39: =MAPA!F26 -> FL 2º SEMESTRE
A40: 4102 C | B40: =MAPA!B27 -> 0 | C40: =MAPA!D27 -> 0 | D40: =MAPA!E28 -> 0 | E40: =MAPA!F27 -> 0
A41: 4103 A | B41: =MAPA!B28 -> 0 | C41: =MAPA!D28 -> 0 | D41: =MAPA!E28 -> 0 | E41: =MAPA!F28 -> 0
A42: 4103 B | B42: =MAPA!B29 -> 0 | C42: =MAPA!D29 -> 0 | D42: =MAPA!E29 -> 0 | E42: =MAPA!F30 -> 0
...

Sheet Etiquetas UTIP
A1: ETIQUETA LACTÁRIO - UTI PEDIÁTRICA
A2: Leito: | B2: =MAPA!A8 -> 4001 | G2: Leito: | H2: =MAPA!A9 -> 4002
A3: Nome: | B3: =MAPA!B8 -> OTAVIO DA SILVEIRA LEMOS,6M | G3: Nome: | H3: =MAPA!B9 -> BEATRIZ RUAS DA SILVA, 1A11M
A4: =MAPA!D8 -> 120 | B4: ml | C4: Via: | D4: =MAPA!C8 -> SNE | E4: =MAPA!G8 -> 3/3H | G4: =MAPA!D9 -> 90 | H4: ml | I4: Via: | J4: =MAPA!C9 -> SNE | K4: =MAPA!G9 -> 3/3H
A5: =MAPA!E8 -> 0 | B5: =MAPA!F8 -> FL HIDROLISADA (15,9%) | G5: =MAPA!E9 -> 0 | H5: =MAPA!F9 -> FORTINI
A6: Horário : | B6: 00h - 06h - 09h - 12h - 15h - 18h - 21h | G6: Horário : | H6: 00h - 06h - 09h - 12h - 15h - 18h - 21h
A7: Manipulação: | C7: =MAPA!A4 -> DATA : 10/10/2019 | G7: Manipulação: | I7: =MAPA!A4 -> DATA : 10/10/2019
A8: 10h-10:30 16h - 16:30 22h-22:30 04h- 04:30 | G8: 10h-10:30 16h - 16:30 22h-22:30 04h- 04:30
A9: Validade: Consumir em até 2h após a entrega. | E9: RT: Tatiana Betina Nantal - CRN2 2240 | G9: Validade: Consumir em até 2h após a entrega. | K9: RT: Tatiana Betina Nantal - CRN2 2240
A10: Temperatura para conservação até 5°C | G10: Temperatura para conservação até 5°C
A12: Leito: | B12: =MAPA!A10 -> 4003 | G12: Leito: | H12: =MAPA!A11 -> 4004
A13: Nome: | B13: =MAPA!B10 -> ANTHONIA JULIA RANZAN 2A5M | G13: Nome: | H13: =MAPA!B11 -> KEIVID LUAN KLAUCK 11A
A14: =MAPA!D10 -> 240 | B14: ml | C14: Via: | D14: =MAPA!C10 -> VO | E14: =MAPA!G11 -> 3/3H | G14: =MAPA!D11 -> 60 | H14: ml | I14: Via: | J14: =MAPA!C11 -> SNE | K14: =MAPA!#REF! -> #REF!
A15: =MAPA!E10 -> 0 | B15: =MAPA!F10 -> LV + ACHOCOLATADO | G15: =MAPA!E11 -> 0 | H15: =MAPA!F11 -> FL HIDROLISADA
A16: Horário : | B16: 00h - 03h - 06h - 09h - 12h - 15h - 18h - 21h | G16: Horário : | H16: 00h - 03h - 06h - 09h - 12h - 15h - 18h - 21h
A17: Manipulação: | C17: =MAPA!A4 -> DATA : 10/10/2019 | G17: Manipulação: | I17: =MAPA!A4 -> DATA : 10/10/2019
A18: 10h-10:30 16h - 16:30 22h-22:30 04h- 04:30 | G18: 10h-10:30 16h - 16:30 22h-22:30 04h- 04:30
A19: Validade: Consumir em até 2h após a entrega. | E19: RT: Tatiana Betina Nantal - CRN2 2240 | G19: Validade: Consumir em até 2h após a entrega. | K19: RT: Tatiana Betina Nantal - CRN2 2240
A20: Temperatura para conservação até 5°C | G20: Temperatura para conservação até 5°C
A23: Leito: | B23: =MAPA!A12 -> 4005 | G23: Leito: | H23: =MAPA!A13 -> 4006
A24: Nome: | B24: =MAPA!B12 -> BIANCA GABRIELLY MACHADO, 6M | G24: Nome: | H24: =MAPA!B13 -> 0
A25: =MAPA!D12 -> 70 | B25: ml | C25: Via: | D25: =MAPA!C12 -> SNE | E25: =MAPA!G12 -> 3/3H | G25: =MAPA!D13 -> 0 | H25: ml | I25: Via: | J25: =MAPA!C13 -> 0 | K25: =MAPA!G13 -> 0
A26: =MAPA!E12 -> 0 | B26: =MAPA!F12 -> FL 1º SEMESTRE | G26: =MAPA!E13 -> 0 | H26: =MAPA!F13 -> 0
A27: Horário : | B27: 00h - 03h - 06h - 09h - 12h - 15h - 18h - 21h | G27: Horário : | H27: 00h - 03h - 06h - 09h - 12h - 15h - 18h - 21h
A28: Manipulação: | C28: =MAPA!A4 -> DATA : 10/10/2019 | G28: Manipulação: | I28: =MAPA!A4 -> DATA : 10/10/2019
A29: 10h-10:30 16h - 16:30 22h-22:30 04h- 04:30 | G29: 10h-10:30 16h - 16:30 22h-22:30 04h- 04:30
A30: Validade: Consumir em até 2h após a entrega. | E30: RT: Tatiana Betina Nantal - CRN2 2240 | G30: Validade: Consumir em até 2h após a entrega. | K30: RT: Tatiana Betina Nantal - CRN2 2240
A31: Temperatura para conservação até 5°C | G31: Temperatura para conservação até 5°C
A34: Leito: | B34: =MAPA!A14 -> 4007 | G34: Leito: | H34: =MAPA!A15 -> 4008
A35: Nome: | B35: =MAPA!B14 -> 0 | G35: Nome: | H35: =MAPA!B15 -> MARIA FLORÊNCIA A. M. DUARTE, 2A3M
A36: =MAPA!D14 -> 0 | B36: ml | C36: Via: | D36: =MAPA!C14 -> 0 | E36: =MAPA!G14 -> 0 | G36: =MAPA!D15 -> 100 | H36: ml | I36: Via: | J36: =MAPA!C15 -> SNE | K36: =MAPA!G15 -> 3/3H
A37: =MAPA!E14 -> 0 | B37: =MAPA!F14 -> 0 | G37: =MAPA!E15 -> - | H37: =MAPA!F15 -> FORTINI
A38: Horário : | B38: 00h - 03h - 06h - 09h - 12h - 15h - 18h - 21h | G38: Horário : | H38: 00h - 03h - 06h - 09h - 12h - 15h - 18h - 21h
A39: Manipulação: | C39: =MAPA!A4 -> DATA : 10/10/2019 | G39: Manipulação: | I39: =MAPA!A4 -> DATA : 10/10/2019
A40: 10h-10:30 16h - 16:30 22h-22:30 04h- 04:30 | G40: 10h-10:30 16h - 16:30 22h-22:30 04h- 04:30
A41: Validade: Consumir em até 2h após a entrega. | E41: RT: Tatiana Betina Nantal - CRN2 2240 | G41: Validade: Consumir em até 2h após a entrega. | K41: RT: Tatiana Betina Nantal - CRN2 2240
A42: Temperatura para conservação até 5°C | G42: Temperatura para conservação até 5°C
A45: Leito: | B45: =MAPA!A16 -> 4009 | G45: Leito: | H45: =MAPA!A17 -> 4010
A46: Nome: | B46: =MAPA!B16 -> 0 | G46: Nome: | H46: =MAPA!B17 -> ALICE MANUELLA DORNELES, 8M
A47: =MAPA!D16 -> 0 | B47: ml | C47: Via: | D47: =MAPA!C16 -> 0 | E47: =MAPA!G16 -> 0 | G47: =MAPA!D17 -> 140 | H47: ml | I47: Via: | J47: =MAPA!C17 -> SNE | K47: =MAPA!G17 -> 3/3H
...

Sheet Etiquetas PED
A1: ETIQUETA LACTÁRIO - INTERNAÇÃO PEDIÁTRICA | M1: RETAGUARDA
A2: Leito: | B2: =MAPA!A22 -> 4101 A | G2: Leito: | H2: =MAPA!A23 -> 4101 B | M2: Leito: | N2: =MAPA!A24 -> 4101 C
A3: Nome: | B3: =MAPA!B22 -> LOUISE REOLON CHUVAS, 4A | G3: Nome: | H3: =MAPA!B23 -> 0 | M3: Nome: | N3: =MAPA!B24 -> 0
A4: =MAPA!D22 -> 240 | B4: ml | C4: Via: | D4: =MAPA!C22 -> VO | E4: =MAPA!G22 -> 7:30-15-21H | G4: =MAPA!D23 -> 0 | H4: ml | I4: Via: | J4: =MAPA!C23 -> 0 | K4: =MAPA!G23 -> 0 | M4: =MAPA!D24 -> 0 | N4: ml | O4: Via: | P4: =MAPA!C24 -> 0 | Q4: =MAPA!G24 -> 0
A5: =MAPA!E22 -> 0 | B5: =MAPA!F22 -> LV+ACHOCOLATADO | G5: =MAPA!E23 -> 0 | H5: =MAPA!F23 -> 0 | M5: =MAPA!E24 -> 0 | N5: =MAPA!F24 -> 0
A6: Horário : | B6: 00h - 03h - 06h - 09h - 12h - 15h - 18h - 21h | G6: Horário : | H6: 00h - 03h - 06h - 09h - 12h - 15h - 18h - 21h | M6: Horário : | N6: 00h - 03h - 06h - 09h - 12h - 15h - 18h - 21h
A7: Manipulação: | C7: =MAPA!A4 -> DATA : 10/10/2019 | G7: Manipulação: | I7: =MAPA!A4 -> DATA : 10/10/2019 | M7: Manipulação: | O7: =MAPA!A4 -> DATA : 10/10/2019
A8: 10h-10:30 16h - 16:30 22h-22:30 04h- 04:30 | G8: 10h-10:30 16h - 16:30 22h-22:30 04h- 04:30 | M8: 10h-10:30 16h - 16:30 22h-22:30 04h- 04:30
A9: Validade: Consumir em até 1h após a entrega. | E9: RT: Tatiana Betina Nantal - CRN2 2240 | G9: Validade: Consumir em até 1h após a entrega. | K9: RT: Tatiana Betina Nantal - CRN2 2240 | M9: Validade: Consumir em até 1h após a entrega. | Q9: RT: Tatiana Betina Nantal - CRN2 2240
A10: Temperatura para conservação até 5°C | G10: Temperatura para conservação até 5°C | M10: Temperatura para conservação até 5°C
A13: Leito: | B13: =MAPA!A25 -> 4102 A | G13: Leito: | H13: =MAPA!A26 -> 4102 B | M13: Leito: | N13: =MAPA!A27 -> 4102 C
A14: Nome: | B14: =MAPA!B25 -> 0 | G14: Nome: | H14: =MAPA!B26 -> LUIZ FELIPE ELIAS SILVA, 9M | M14: Nome: | N14: =MAPA!B28 -> 0
A15: =MAPA!D25 -> 0 | B15: ml | C15: Via: | D15: =MAPA!C25 -> 0 | E15: =MAPA!G25 -> 0 | G15: =MAPA!D26 -> 200 | H15: ml | I15: Via: | J15: =MAPA!C26 -> VO | K15: =MAPA!G26 -> 3/3H (-18 -03H -09H) | M15: =MAPA!D29 -> 0 | N15: ml | O15: Via: | P15: =MAPA!C29 -> 0 | Q15: =MAPA!G29 -> 0
A16: =MAPA!E25 -> 0 | B16: =MAPA!F25 -> 0 | G16: =MAPA!E26 -> 0 | H16: =MAPA!F26 -> FL 2º SEMESTRE | M16: =MAPA!E29 -> 0 | N16: =MAPA!F30 -> 0
A17: Horário : | B17: 00h - 03h - 06h - 09h - 12h - 15h - 18h - 21h | G17: Horário : | H17: 00h - 03h - 06h - 09h - 12h - 15h - 18h - 21h | M17: Horário : | N17: 00h - 03h - 06h - 09h - 12h - 15h - 18h - 21h
A18: Manipulação: | C18: =MAPA!A4 -> DATA : 10/10/2019 | G18: Manipulação: | I18: =MAPA!A4 -> DATA : 10/10/2019 | M18: Manipulação: | O18: =MAPA!A4 -> DATA : 10/10/2019
A19: 10h-10:30 16h - 16:30 22h-22:30 04h- 04:30 | G19: 10h-10:30 16h - 16:30 22h-22:30 04h- 04:30 | M19: 10h-10:30 16h - 16:30 22h-22:30 04h- 04:30
A20: Validade: Consumir em até 2h após a entrega. | E20: RT: Tatiana Betina Nantal - CRN2 2240 | G20: Validade: Consumir em até 2h após a entrega. | K20: RT: Tatiana Betina Nantal - CRN2 2240 | M20: Validade: Consumir em até 2h após a entrega. | Q20: RT: Tatiana Betina Nantal - CRN2 2240
A21: Temperatura para conservação até 5°C | G21: Temperatura para conservação até 5°C | M21: Temperatura para conservação até 5°C
A24: Leito: | B24: =MAPA!A28 -> 4103 A | G24: Leito: | H24: =MAPA!A29 -> 4103 B | M24: Leito: | N24: =MAPA!A30 -> 4103 C
A25: Nome: | B25: =MAPA!B28 -> 0 | G25: Nome: | H25: =MAPA!B29 -> 0 | M25: Nome: | N25: =MAPA!B30 -> 0
A26: =MAPA!D28 -> 0 | B26: ml | C26: Via: | D26: =MAPA!C28 -> 0 | E26: =MAPA!G28 -> 0 | G26: =MAPA!D29 -> 0 | H26: ml | I26: Via: | J26: =MAPA!C29 -> 0 | K26: =MAPA!G29 -> 0 | M26: =MAPA!D30 -> 0 | N26: ml | O26: Via: | P26: =MAPA!C30 -> 0 | Q26: =MAPA!G30 -> 0
A27: =MAPA!#REF! -> #REF! | B27: =MAPA!F28 -> 0 | G27: =MAPA!E29 -> 0 | H27: =MAPA!F30 -> 0 | M27: =MAPA!E30 -> 0 | N27: =MAPA!#REF! -> #REF!
A28: Horário : | B28: 00h - 03h - 06h - 09h - 12h - 15h - 18h - 21h | G28: Horário : | H28: 00h - 03h - 06h - 09h - 12h - 15h - 18h - 21h | M28: Horário : | N28: 00h - 03h - 06h - 09h - 12h - 15h - 18h - 21h
A29: Manipulação: | C29: =MAPA!A4 -> DATA : 10/10/2019 | G29: Manipulação: | I29: =MAPA!A4 -> DATA : 10/10/2019 | M29: Manipulação: | O29: =MAPA!A4 -> DATA : 10/10/2019
A30: 10h-10:30 16h - 16:30 22h-22:30 04h- 04:30 | G30: 10h-10:30 16h - 16:30 22h-22:30 04h- 04:30 | M30: 10h-10:30 16h - 16:30 22h-22:30 04h- 04:30
A31: Validade: Consumir em até 1h após a entrega. | E31: RT: Tatiana Betina Nantal - CRN2 2240 | G31: Validade: Consumir em até 1h após a entrega. | K31: RT: Tatiana Betina Nantal - CRN2 2240 | M31: Validade: Consumir em até 1h após a entrega. | Q31: RT: Tatiana Betina Nantal - CRN2 2240
A32: Temperatura para conservação até 5°C | G32: Temperatura para conservação até 5°C | M32: Temperatura para conservação até 5°C
A35: Leito: | B35: =MAPA!A31 -> 4104 A | G35: Leito: | H35: =MAPA!A32 -> 4104 B | M35: Leito: | N35: =MAPA!A33 -> 4104 C
A36: Nome: | B36: =MAPA!B31 -> 0 | G36: Nome: | H36: =MAPA!B32 -> 0 | M36: Nome: | N36: =MAPA!B33 -> 0
A37: =MAPA!D31 -> 0 | B37: ml | C37: Via: | D37: =MAPA!C31 -> 0 | E37: =MAPA!G31 -> 0 | G37: =MAPA!D32 -> 0 | H37: ml | I37: Via: | J37: =MAPA!C32 -> 0 | K37: =MAPA!G32 -> 0 | M37: =MAPA!D33 -> 0 | N37: ml | O37: Via: | P37: =MAPA!C33 -> 0 | Q37: =MAPA!G33 -> 0
A38: =MAPA!E31 -> 0 | B38: =MAPA!F31 -> 0 | G38: =MAPA!E32 -> 0 | H38: =MAPA!F32 -> 0 | M38: =MAPA!E33 -> 0 | N38: =MAPA!F33 -> 0
A39: Horário : | B39: 00h - 03h - 06h - 09h - 12h - 15h - 18h - 21h | G39: Horário : | H39: 00h - 03h - 06h - 09h - 12h - 15h - 18h - 21h | M39: Horário : | N39: 00h - 03h - 06h - 09h - 12h - 15h - 18h - 21h
A40: Manipulação: | C40: =MAPA!A4 -> DATA : 10/10/2019 | G40: Manipulação: | I40: =MAPA!A4 -> DATA : 10/10/2019 | M40: Manipulação: | O40: =MAPA!A4 -> DATA : 10/10/2019
A41: 10h-10:30 16h - 16:30 22h-22:30 04h- 04:30 | G41: 10h-10:30 16h - 16:30 22h-22:30 04h- 04:30 | M41: 10h-10:30 16h - 16:30 22h-22:30 04h- 04:30
A42: Validade: Consumir em até 1h após a entrega. | E42: RT: Tatiana Betina Nantal - CRN2 2240 | G42: Validade: Consumir em até 1h após a entrega. | K42: RT: Tatiana Betina Nantal - CRN2 2240 | M42: Validade: Consumir em até 1h após a entrega. | Q42: RT: Tatiana Betina Nantal - CRN2 2240
A43: Temperatura para conservação até 5°C | G43: Temperatura para conservação até 5°C | M43: Temperatura para conservação até 5°C
A46: Leito: | B46: =MAPA!A34 -> 4105 A | G46: Leito: | H46: =MAPA!A35 -> 4105 B | M46: Leito: | N46: =MAPA!A36 -> 4105 C
A47: Nome: | B47: =MAPA!B34 -> 0 | G47: Nome: | H47: =MAPA!B35 -> 0 | M47: Nome: | N47: =MAPA!B36 -> 0
A48: =MAPA!D34 -> 0 | B48: ml | C48: Via: | D48: =MAPA!C34 -> 0 | E48: =MAPA!G34 -> 0 | G48: =MAPA!D35 -> 0 | H48: ml | I48: Via: | J48: =MAPA!C35 -> 0 | K48: =MAPA!G35 -> 0 | M48: =MAPA!D36 -> 0 | N48: ml | O48: Via: | P48: =MAPA!C36 -> 0 | Q48: =MAPA!G36 -> 0
...

Sheet Etiquetas CTI Neo
A1: ETIQUETA LACTÁRIO - UTI NEONATAL
A2: Leito: | B2: =MAPA!A68 -> 4201 | G2: Leito: | H2: =MAPA!A69 -> 4202
A3: Nome: | B3: =MAPA!B68 -> RN DE MAIRA ALEXANDRA (Augusto) | G3: Nome: | H3: =MAPA!B69 -> 0
A4: =MAPA!D68 -> 40 | B4: ml | C4: Via: | D4: =MAPA!C68 -> SOG | E4: =MAPA!G69 -> 0 | G4: =MAPA!D69 -> 0 | H4: ml | I4: Via: | J4: =MAPA!C69 -> 0 | K4: =MAPA!#REF! -> #REF!
A5: =MAPA!E68 -> LM | B5: =MAPA!F68 -> FL TRANSIÇÃO | G5: =MAPA!E69 -> 0 | H5: =MAPA!F69 -> 0
A6: Horário : | B6: 00h - 03h - 06h - 09h - 12h - 15h - 18h - 21h | G6: Horário : | H6: 00h - 03h - 06h - 09h - 12h - 15h - 18h - 21h
A7: Manipulação: | C7: =MAPA!A4 -> DATA : 10/10/2019 | G7: Manipulação: | I7: =MAPA!A4 -> DATA : 10/10/2019
A8: 10h-10:30 16h - 16:30 22h-22:30 04h- 04:30 | G8: 10h-10:30 16h - 16:30 22h-22:30 04h- 04:30
A9: Validade: Consumir em até 1h após a entrega. | E9: RT: Tatiana Betina Nantal - CRN2 2240 | G9: Validade: Consumir em até 1h após a entrega. | K9: RT: Tatiana Betina Nantal - CRN2 2240
A10: Temperatura para conservação até 5°C | G10: Temperatura para conservação até 5°C
A13: Leito: | B13: =MAPA!A70 -> 4203 | G13: Leito: | H13: =MAPA!A71 -> 4204
A14: Nome: | B14: =MAPA!B70 -> RN DE ANA CLAUDIA VARGAS (Manuela) | G14: Nome: | H14: =MAPA!B71 -> RN DE TAINARA DE CARVALHO BOTELHO (Jhon Peter)
A15: =MAPA!D70 -> 32 | B15: ml | C15: Via: | D15: =MAPA!C70 -> SOG | E15: =MAPA!G70 -> 3/3H | G15: =MAPA!D71 -> 25 | H15: ml | I15: Via: | J15: =MAPA!C71 -> SNG | K15: =MAPA!G71 -> 3/3H
A16: =MAPA!E70 -> LM + FM | B16: =MAPA!F70 -> FL PREMATURO | G16: =MAPA!E71 -> LM | H16: =MAPA!F71 -> FL PREMATURO
A17: Horário : | B17: 00h - 03h - 06h - 09h - 12h - 15h - 18h - 21h | G17: Horário : | H17: 00h - 03h - 06h - 09h - 12h - 15h - 18h - 21h
A18: Manipulação: | C18: =MAPA!A4 -> DATA : 10/10/2019 | G18: Manipulação: | I18: =MAPA!A4 -> DATA : 10/10/2019
A19: 10h-10:30 16h - 16:30 22h-22:30 04h- 04:30 | G19: 10h-10:30 16h - 16:30 22h-22:30 04h- 04:30
A20: Validade: Consumir em até 1h após a entrega. | E20: RT: Tatiana Betina Nantal - CRN2 2240 | G20: Validade: Consumir em até 1h após a entrega. | K20: RT: Tatiana Betina Nantal - CRN2 2240
A21: Temperatura para conservação até 5°C | G21: Temperatura para conservação até 5°C
A24: Leito: | B24: =MAPA!A72 -> 4205 | G24: Leito: | H24: =MAPA!A73 -> 4206
A25: Nome: | B25: =MAPA!B72 -> RN ELISSANGELA MENDES | G25: Nome: | H25: =MAPA!B73 -> RN DE JENIFER VITÓRIA (Oliver)
A26: =MAPA!D72 -> 31 | B26: ml | C26: Via: | D26: =MAPA!C72 -> VO | E26: =MAPA!G72 -> 3/3H | G26: =MAPA!D73 -> 16 | H26: ml | I26: Via: | J26: =MAPA!C73 -> SOG | K26: =MAPA!G73 -> 3/3H
A27: =MAPA!E72 -> LM | B27: =MAPA!F72 -> FL 1º SEMESTRE | G27: =MAPA!#REF! -> #REF! | H27: =MAPA!E73 -> LM
A28: Horário : | B28: 00h - 03h - 06h - 09h - 12h - 15h - 18h - 21h | G28: Horário : | H28: 00h - 03h - 06h - 09h - 12h - 15h - 18h - 21h
A29: Manipulação: | C29: =MAPA!A4 -> DATA : 10/10/2019 | G29: Manipulação: | I29: =MAPA!A4 -> DATA : 10/10/2019
A30: 10h-10:30 16h - 16:30 22h-22:30 04h- 04:30 | G30: 10h-10:30 16h - 16:30 22h-22:30 04h- 04:30
A31: Validade: Consumir em até 1h após a entrega. | E31: RT: Tatiana Betina Nantal - CRN2 2240 | G31: Validade: Consumir em até 1h após a entrega. | K31: RT: Tatiana Betina Nantal - CRN2 2240
A32: Temperatura para conservação até 5°C | G32: Temperatura para conservação até 5°C
A35: Leito: | B35: =MAPA!A74 -> 4207 | G35: Leito: | H35: =MAPA!A75 -> 4208
A36: Nome: | B36: =MAPA!B74 -> RN GIOVANA MEDEIROS (Camila) | G36: Nome: | H36: =MAPA!B75 -> 0
A37: =MAPA!D74 -> 62 | B37: ml | C37: Via: | D37: =MAPA!C74 -> VO | E37: =MAPA!G74 -> 3/3H | G37: =MAPA!D75 -> 0 | H37: ml | I37: Via: | J37: =MAPA!C75 -> 0 | K37: =MAPA!G75 -> 0
A38: =MAPA!E74 -> LM | B38: =MAPA!F74 -> FL 1º SEMESTRE | G38: =MAPA!E75 -> 0 | H38: =MAPA!F75 -> 0
A39: Horário : | B39: 00h - 03h - 06h - 09h - 12h - 15h - 18h - 21h | G39: Horário : | H39: 00h - 03h - 06h - 09h - 12h - 15h - 18h - 21h
A40: Manipulação: | C40: =MAPA!A4 -> DATA : 10/10/2019 | G40: Manipulação: | I40: =MAPA!A4 -> DATA : 10/10/2019
A41: 10h-10:30 16h - 16:30 22h-22:30 04h- 04:30 | G41: 10h-10:30 16h - 16:30 22h-22:30 04h- 04:30
A42: Validade: Consumir em até 1h após a entrega. | E42: RT: Tatiana Betina Nantal - CRN2 2240 | G42: Validade: Consumir em até 1h após a entrega. | K42: RT: Tatiana Betina Nantal - CRN2 2240
A43: Temperatura para conservação até 5°C | G43: Temperatura para conservação até 5°C
A46: Leito: | B46: =MAPA!A76 -> 4209 | G46: Leito: | H46: =MAPA!A77 -> 4210
A47: Nome: | B47: =MAPA!B76 -> RN DE DANIELA ARAGÃO MAUER (Marco Antônio) | G47: Nome: | H47: =MAPA!B77 -> RN DE DEZERRE DA ROSA AGUIRRE (Murilo)
A48: =MAPA!D76 -> 50 | B48: ml | C48: Via: | D48: =MAPA!C76 -> SOG | E48: =MAPA!G16 -> 0 | G48: =MAPA!D77 -> 50 | H48: ml | I48: Via: | J48: =MAPA!C77 -> VO | K48: =MAPA!G77 -> 3/3H
...

Sheet Etiquetas AC
A1: ETIQUETA LACTÁRIO - Alojamento Conjunto
A2: Leito: | G2: Leito:
A3: Nome: | G3: Nome:
B4: ml | C4: Via: | D4: VO | E4: 1º SEMESTRE | H4: ml | I4: Via:
A6: Horário : | B6: 00h - 03h - 06h - 09h - 12h - 15h - 18h - 21h | G6: Horário : | H6: 00h - 03h - 06h - 09h - 12h - 15h - 18h - 21h
A7: Manipulação: | C7: =MAPA!A4 -> DATA : 10/10/2019 | G7: Manipulação: | I7: =MAPA!A4 -> DATA : 10/10/2019
A8: 10h-10:30 16h - 16:30 22h-22:30 04h- 04:30 | G8: 10h-10:30 16h - 16:30 22h-22:30 04h- 04:30
A9: Validade: Consumir em até 2h após a entrega. | E9: RT: Tatiana Betina Nantal - CRN2 2240 | G9: Validade: Consumir em até 2h após a entrega. | K9: RT: Tatiana Betina Nantal - CRN2 2240
A10: Temperatura para conservação até 5°C | G10: Temperatura para conservação até 5°C
A13: Leito: | G13: Leito:
G14: Nome:
B15: ml | C15: Via: | D15: VO | H15: ml | I15: Via:
A17: Horário : | B17: 00h - 03h - 06h - 09h - 12h - 15h - 18h - 21h | G17: Horário : | H17: 00h - 03h - 06h - 09h - 12h - 15h - 18h - 21h
A18: Manipulação: | C18: =MAPA!A4 -> DATA : 10/10/2019 | G18: Manipulação: | I18: =MAPA!A4 -> DATA : 10/10/2019
A19: 10h-10:30 16h - 16:30 22h-22:30 04h- 04:30 | G19: 10h-10:30 16h - 16:30 22h-22:30 04h- 04:30
A20: Validade: Consumir em até 2h após a entrega. | E20: RT: Tatiana Betina Nantal - CRN2 2240 | G20: Validade: Consumir em até 2h após a entrega. | K20: RT: Tatiana Betina Nantal - CRN2 2240
A21: Temperatura para conservação até 5°C | G21: Temperatura para conservação até 5°C
A24: Leito: | G24: Leito:
A25: Nome: | G25: Nome:
B26: ml | C26: Via: | H26: ml | I26: Via:
A28: Horário : | B28: 00h - 03h - 06h - 09h - 12h - 15h - 18h - 21h | G28: Horário : | H28: 00h - 03h - 06h - 09h - 12h - 15h - 18h - 21h
A29: Manipulação: | C29: =MAPA!A4 -> DATA : 10/10/2019 | G29: Manipulação: | I29: =MAPA!A4 -> DATA : 10/10/2019
A30: 10h-10:30 16h - 16:30 22h-22:30 04h- 04:30 | G30: 10h-10:30 16h - 16:30 22h-22:30 04h- 04:30
A31: Validade: Consumir em até 2h após a entrega. | E31: RT: Tatiana Betina Nantal - CRN2 2240 | G31: Validade: Consumir em até 2h após a entrega. | K31: RT: Tatiana Betina Nantal - CRN2 2240
A32: Temperatura para conservação até 5°C | G32: Temperatura para conservação até 5°C
A35: Leito: | G35: Leito:
A36: Nome: | G36: Nome:
B37: ml | C37: Via: | H37: ml | I37: Via:
A39: Horário : | B39: 00h - 03h - 06h - 09h - 12h - 15h - 18h - 21h | G39: Horário : | H39: 00h - 03h - 06h - 09h - 12h - 15h - 18h - 21h
A40: Manipulação: | C40: =MAPA!A4 -> DATA : 10/10/2019 | G40: Manipulação: | I40: =MAPA!A4 -> DATA : 10/10/2019
A41: 10h-10:30 16h - 16:30 22h-22:30 04h- 04:30 | G41: 10h-10:30 16h - 16:30 22h-22:30 04h- 04:30
A42: Validade: Consumir em até 2h após a entrega. | E42: RT: Tatiana Betina Nantal - CRN2 2240 | G42: Validade: Consumir em até 2h após a entrega. | K42: RT: Tatiana Betina Nantal - CRN2 2240
A43: Temperatura para conservação até 5°C | G43: Temperatura para conservação até 5°C
A46: Leito: | G46: Leito:
A47: Nome: | G47: Nome:
B48: ml | C48: Via: | H48: ml | I48: Via:
A50: Horário : | B50: 00h - 03h - 06h - 09h - 12h - 15h - 18h - 21h | G50: Horário : | H50: 00h - 03h - 06h - 09h - 12h - 15h - 18h - 21h
A51: Manipulação: | C51: =MAPA!A4 -> DATA : 10/10/2019 | G51: Manipulação: | I51: =MAPA!A4 -> DATA : 10/10/2019
A52: 10h-10:30 16h - 16:30 22h-22:30 04h- 04:30 | G52: 10h-10:30 16h - 16:30 22h-22:30 04h- 04:30
A53: Validade: Consumir em até 2h após a entrega. | E53: RT: Tatiana Betina Nantal - CRN2 2240 | G53: Validade: Consumir em até 2h após a entrega. | K53: RT: Tatiana Betina Nantal - CRN2 2240
...

Sheet Plan1

Sheet Plan2
